Fehlermeldung:

Traceback (most recent call last):
  File "/usr/lib/python3.8/site-packages/urllib3/connection.py", line 159, in _new_conn
    conn = connection.create_connection(
  File "/usr/lib/python3.8/site-packages/urllib3/util/connection.py", line 61, in create_connection
    for res in socket.getaddrinfo(host, port, family, socket.SOCK_STREAM):
  File "/usr/lib/python3.8/socket.py", line 918, in getaddrinfo
    for res in _socket.getaddrinfo(host, port, family, type, proto, flags):
socket.gaierror: [Errno -3] Try again
During handling of the above exception, another exception occurred:
Traceback (most recent call last):
  File "/usr/lib/python3.8/site-packages/urllib3/connectionpool.py", line 670, in urlopen
    httplib_response = self._make_request(
  File "/usr/lib/python3.8/site-packages/urllib3/connectionpool.py", line 381, in _make_request
    self._validate_conn(conn)
  File "/usr/lib/python3.8/site-packages/urllib3/connectionpool.py", line 976, in _validate_conn
    conn.connect()
  File "/usr/lib/python3.8/site-packages/urllib3/connection.py", line 308, in connect
    conn = self._new_conn()
  File "/usr/lib/python3.8/site-packages/urllib3/connection.py", line 171, in _new_conn
    raise NewConnectionError(
urllib3.exceptions.NewConnectionError: <urllib3.connection.HTTPSConnection object at 0x7fb98279a730>: Failed to establish a new connection: [Errno -3] Try again
During handling of the above exception, another exception occurred:
Traceback (most recent call last):
  File "/usr/lib/python3.8/site-packages/requests/adapters.py", line 439, in send
    resp = conn.urlopen(
  File "/usr/lib/python3.8/site-packages/urllib3/connectionpool.py", line 724, in urlopen
    retries = retries.increment(
  File "/usr/lib/python3.8/site-packages/urllib3/util/retry.py", line 439, in increment
    raise MaxRetryError(_pool, url, error or ResponseError(cause))
urllib3.exceptions.MaxRetryError: HTTPSConnectionPool(host='api.openweathermap.org', port=443): Max retries exceeded with url: /data/3.0/onecall?lat=33.44&lon=-94.04&appid=1fb87269c7a756df23755ec6a7824732 (Caused by NewConnectionError('<urllib3.connection.HTTPSConnection object at 0x7fb98279a730>: Failed to establish a new connection: [Errno -3] Try again'))
During handling of the above exception, another exception occurred:
Traceback (most recent call last):
  File "main.py", line 14, in <module>
    wetterDaten = holeWetterDaten(stadt)
  File "main.py", line 6, in holeWetterDaten
    antwort = requests.get(url)
  File "/usr/lib/python3.8/site-packages/requests/api.py", line 76, in get
    return request('get', url, params=params, **kwargs)
  File "/usr/lib/python3.8/site-packages/requests/api.py", line 61, in request
    return session.request(method=method, url=url, **kwargs)
  File "/usr/lib/python3.8/site-packages/requests/sessions.py", line 530, in request
    resp = self.send(prep, **send_kwargs)
  File "/usr/lib/python3.8/site-packages/requests/sessions.py", line 643, in send
    r = adapter.send(request, **kwargs)
  File "/usr/lib/python3.8/site-packages/requests/adapters.py", line 516, in send
    raise ConnectionError(e, request=request)
requests.exceptions.ConnectionError: HTTPSConnectionPool(host='api.openweathermap.org', port=443): Max retries exceeded with url: /data/3.0/onecall?lat=33.44&lon=-94.04&appid=1fb87269c7a756df23755ec6a7824732 (Caused by NewConnectionError('<urllib3.connection.HTTPSConnection object at 0x7fb98279a730>: Failed to establish a new connection: [Errno -3] Try again'))


** Process exited - Return Code: 1 **
Press Enter to exit terminal
